Workbook

Sheet DS
AA1: VALVE DATA SHEET | BX1: Sheet No. | CD1: 1 OF 1 | CL1: 엑셀 매크로 (자동입력)
AA2: Item | AJ2: 155 | CL2: ACTUATOR | CQ2: ACCESSORY
AA3: Project | AJ3: 1
AA4: Service | CM4: 1. Model No | CR4: POSITIONER
AA5: Tag. No. | AJ5: 3 | BO5: MFG. No. | CM5: ㄴ MFG | CN5: PROVAL 고정? | CR5: ㄴ MFG | CS5: =IFERROR( IF(INDEX(ACC!F:F, MATCH(CS4, ACC!A:A, 0)) = "", "-", INDEX(ACC!F:F, MATCH(CS4, ACC!A:A, 0))), "-" ) -> -
AA6: Model No. | BO6: Q'ty (Set) | BX6: 4 | CM6: ㄴ MODEL | CN6: =IFERROR( IF(INDEX(ACT!C:C, MATCH(CN4,ACT!B:B, 0))="", "-", INDEX(ACT!C:C, MATCH(CN4,ACT!B:B, 0))), "-" ) -> - | CR6: ㄴ MODEL | CS6: =IFERROR( IF(INDEX(ACC!E:E, MATCH(CS4, ACC!A:A, 0)) = "", "-", INDEX(ACC!E:E, MATCH(CS4, ACC!A:A, 0))), "-" ) -> -
CM7: ㄴ Type | CN7: {=IFERROR( IF(INDEX(ACT!M:M,MATCH(1,(ACT!H:H=CN18)*(ACT!I:I=CN17),0))="", "-", INDEX(ACT!M:M,MATCH(1,(ACT!H:H=CN18)*(ACT!I:I=CN17),0))), "-" )} -> - | CO7: =IFERROR( IF(INDEX(ACT!F:F, MATCH(CN4,ACT!B:B, 0)) = "", "-", INDEX(ACT!F:F, MATCH(CN4,ACT!B:B, 0))), "-" ) -> - | CR7: ㄴ Type | CS7: =IFERROR( IF(INDEX(ACC!C:C, MATCH(CS4, ACC!A:A, 0)) = "", "-", INDEX(ACC!C:C, MATCH(CS4, ACC!A:A, 0))), "-" ) -> -
A8: SERVICE CONDITIONS | E8: 1 | H8: Medium | V8: 22 | AI8: 23 | AT8: ACTUATOR | AX8: 46 | BA8: Actuator Type | BQ8: =_xlfn.TEXTJOIN(" ", TRUE, IF(CN7<>"-", CN7, ""), IF(CO7<>"-", CO7, "") ) | CM8: ㄴ Close/Open At | CN8: {=IFERROR( IF(INDEX(ACT!K:K,MATCH(1,(ACT!H:H=CN18)*(ACT!I:I=CN17),0))="", "-", INDEX(ACT!K:K,MATCH(1,(ACT!H:H=CN18)*(ACT!I:I=CN17),0))), "-" )} -> - | CO8: {=IFERROR( IF(INDEX(ACT!L:L,MATCH(1,(ACT!H:H=CN18)*(ACT!I:I=CN17),0))="", "-", INDEX(ACT!L:L,MATCH(1,(ACT!H:H=CN18)*(ACT!I:I=CN17),0))), "-" )} -> - | CR8: ㄴ Enclosure | CS8: =IFERROR( IF(INDEX(ACC!D:D, MATCH(CS4, ACC!A:A, 0)) = "", "-", INDEX(ACC!D:D, MATCH(CS4, ACC!A:A, 0))), "-" ) -> -
E9: 2 | V9: Max. Q | AD9: Nor. Q | AL9: Min. Q | AX9: 47 | BA9: Model No. | BQ9: =IF(CN6="", "-", CN6) -> - | CM9: ㄴ Painting Color | CN9: =IFERROR( IF(INDEX(ACT!D:D, MATCH(CN4,ACT!B:B, 0))="", "-", INDEX(ACT!D:D, MATCH(CN4,ACT!B:B, 0))), "-" ) -> - | CR9: ㄴ Input Signal | CS9: =IFERROR( IF(INDEX(ACC!B:B, MATCH(CS4, ACC!A:A, 0)) = "", "-", INDEX(ACC!B:B, MATCH(CS4, ACC!A:A, 0))), "-" ) -> -
E10: 3 | H10: Flow Rate | Q10: 47 / 51 | V10: 44 / 48 | AD10: 45 / 49 | AL10: 46 / 50 | AX10: 48 | BA10: Close At (bar G) | BI10: Open At (bar G) | BQ10: =IF(CN8="", "-", CN8) -> - | CA10: =IF(CO8="", "-", CO8) -> - | CM10: ㄴ Painting Type | CN10: =IFERROR( IF(INDEX(ACT!E:E, MATCH(CN4,ACT!B:B, 0))="", "-", INDEX(ACT!E:E, MATCH(CN4,ACT!B:B, 0))), "-" ) -> - | CR10: ㄴ PTM Output | CS10: =IFERROR( IF(INDEX(ACC!G:G, MATCH(CS4, ACC!A:A, 0)) = "", "-", INDEX(ACC!G:G, MATCH(CS4, ACC!A:A, 0))), "-" ) -> -
E11: 4 | H11: Inlet Pressure | Q11: 35 | V11: 32 | AD11: 33 | AL11: 34 | AX11: 49 | BA11: Fail Position (Signal / Air) | BQ11: {=IFERROR( IF(INDEX(ACT!J:J,MATCH(1,(ACT!H:H=CN18)*(ACT!I:I=CN17),0))="", "-", INDEX(ACT!J:J,MATCH(1,(ACT!H:H=CN18)*(ACT!I:I=CN17),0))), "-" )} -> - | CM11: 2. Handel | CR11: ㄴ PTM Type | CS11: =IFERROR( IF(INDEX(ACC!H:H, MATCH(CS4, ACC!A:A, 0)) = "", "-", INDEX(ACC!H:H, MATCH(CS4, ACC!A:A, 0))), "-" ) -> -
E12: 5 | H12: Outlet Pressure | Q12: 39 | V12: 36 | AD12: 37 | AL12: 38 | AX12: 50 | BA12: Painting Color (RAL No.) | BQ12: =IF(CN9="", "-", CN9) -> - | CM12: ㄴ Type / Location | CN12: =IFERROR( IF(INDEX(ACT!O:O, MATCH(CN11,ACT!N:N, 0))="", "-", INDEX(ACT!O:O, MATCH(CN11,ACT!N:N, 0))), "-" ) -> - | CR12: Solenoid Valve
E13: 6 | H13: Differential Pressure | Q13: 43 | V13: 40 | AD13: 41 | AL13: 42 | AX13: 51 | BA13: Painting Type | BQ13: =IF(CN10="", "-", CN10) -> - | CM13: ㄴ H.W Painting Color | CN13: =IFERROR( IF(INDEX(ACT!P:P, MATCH(CN11,ACT!N:N, 0))="", "-", INDEX(ACT!P:P, MATCH(CN11,ACT!N:N, 0))), "-" ) -> - | CR13: ㄴ MFG | CS13: =IFERROR( IF(INDEX(ACC!R:R, MATCH(CS12, ACC!M:M, 0)) = "", "-", INDEX(ACC!R:R, MATCH(CS12, ACC!M:M, 0))), "-" ) -> -
E14: 7 | H14: Inlet Temperature | Q14: 31 | V14: 28 | AD14: 29 | AL14: 30 | AT14: HAND WHEEL | AX14: 52 | BA14: Type / Location | BQ14: =IF(CN12="", "-", CN12) -> - | CM14: ㄴ H.W Painting Type | CN14: =IFERROR( IF(INDEX(ACT!Q:Q, MATCH(CN11,ACT!N:N, 0))="", "-", INDEX(ACT!Q:Q, MATCH(CN11,ACT!N:N, 0))), "-" ) -> - | CR14: ㄴ MODEL | CS14: =IFERROR( IF(INDEX(ACC!Q:Q, MATCH(CS12, ACC!M:M, 0)) = "", "-", INDEX(ACC!Q:Q, MATCH(CS12, ACC!M:M, 0))), "-" ) -> -
E15: 8 | H15: Specific Gravity | Q15: G | AX15: 53 | BA15: Painting Color (RAL No.) | BQ15: =IF(CN13="", "-", CN13) -> - | CR15: ㄴ Power | CS15: =IFERROR( IF(INDEX(ACC!N:N, MATCH(CS12, ACC!M:M, 0)) = "", "-", INDEX(ACC!N:N, MATCH(CS12, ACC!M:M, 0))), "-" ) -> -
E16: 9 | H16: Density | Q16: 25 | V16: 24 | AD16: 24 | AL16: 24 | AX16: 54 | BA16: Painting Type | BQ16: =IF(CN14="", "-", CN14) -> - | CR16: ㄴ Type | CS16: =IFERROR( IF(INDEX(ACC!O:O, MATCH(CS12, ACC!M:M, 0)) = "", "-", INDEX(ACC!O:O, MATCH(CS12, ACC!M:M, 0))), "-" ) -> -
E17: 10 | H17: Molecular Weight | Q17: 27 | V17: 26 | AD17: 26 | AL17: 26 | AT17: I / P POSITIONER | AX17: 55 | BA17: Input Signal (mA DC) | BQ17: =CS9 -> - | CR17: ㄴ Enclosure | CS17: =IFERROR( IF(INDEX(ACC!P:P, MATCH(CS12, ACC!M:M, 0)) = "", "-", INDEX(ACC!P:P, MATCH(CS12, ACC!M:M, 0))), "-" ) -> -
E18: 11 | H18: Viscosity | Q18: cPs | AX18: 56 | BA18: Type | BQ18: =IF(CS7="", "-", CS7) -> - | CR18: Limit Switch
E19: 12 | H19: Predicted SPL | Q19: dB(A) | V19: 63 | AD19: 64 | AL19: 65 | AX19: 57 | BA19: Enclosure | BQ19: =IF(CS8="", "-", CS8) -> - | CR19: ㄴ MFG | CS19: =IFERROR( IF(INDEX(ACC!X:X, MATCH(CS18, ACC!S:S, 0)) = "", "-", INDEX(ACC!X:X, MATCH(CS18, ACC!S:S, 0))), "-" ) -> -
E20: 13 | H20: Calculated Cv | Q20: 59 | V20: 56 | AD20: 57 | AL20: 58 | AX20: 58 | BA20: Model No. | BI20: MFG. | BQ20: =IF(CS6="", "-", CS6) -> - | CA20: =IF(CS5="", "-", CS5) -> - | CR20: ㄴ MODEL | CS20: =IFERROR( IF(INDEX(ACC!W:W, MATCH(CS18, ACC!S:S, 0)) = "", "-", INDEX(ACC!W:W, MATCH(CS18, ACC!S:S, 0))), "-" ) -> -
E21: 14 | H21: Opening Lift | Q21: % | V21: 60 | AD21: 61 | AL21: 62 | AT21: POSITION TRANSMITTER | AX21: 59 | BA21: Output (mA DC) | BQ21: =IF(CS10="", "-", CS10) -> - | CR21: ㄴ Quantity | CS21: =IFERROR( IF(INDEX(ACC!T:T, MATCH(CS18, ACC!S:S, 0)) = "", "-", INDEX(ACC!T:T, MATCH(CS18, ACC!S:S, 0))), "-" ) -> -
E22: 15 | AX22: 60 | BA22: Type | BQ22: =IF(CS11="", "-", CS11) -> - | CR22: ㄴ Type | CS22: =IFERROR( IF(INDEX(ACC!U:U, MATCH(CS18, ACC!S:S, 0)) = "", "-", INDEX(ACC!U:U, MATCH(CS18, ACC!S:S, 0))), "-" ) -> -
E23: 16 | AT23: AIR SET | AX23: 61 | BA23: Supply Setting Pressure (bar G) | BQ23: =IF(CS27="", "-", CS27) -> - | CR23: ㄴ Enclosure | CS23: =IFERROR( IF(INDEX(ACC!V:V, MATCH(CS18, ACC!S:S, 0)) = "", "-", INDEX(ACC!V:V, MATCH(CS18, ACC!S:S, 0))), "-" ) -> -
A24: LINE | E24: 17 | H24: Shut Off △P | AX24: 62 | BA24: Model No. | BI24: MFG. | BQ24: =IF(CS26="", "-", CS26) -> - | CA24: =IF(CS25="", "-", CS25) -> - | CR24: Air-set
E25: 18 | H25: Design | R25: Pressure | AT25: SOLENOID VALVE | AX25: 63 | BA25: Power | BQ25: =IF(CS15="", "-", CS15) -> - | CR25: ㄴ MFG | CS25: =IFERROR( IF(INDEX(ACC!L:L, MATCH(CS24, ACC!I:I, 0)) = "", "-", INDEX(ACC!L:L, MATCH(CS24, ACC!I:I, 0))), "-" ) -> -
E26: 19 | R26: Temp. | AX26: 64 | BA26: Type | BQ26: =IF(CS16="", "-", CS16) -> - | CR26: ㄴ MODEL | CS26: =IFERROR( IF(INDEX(ACC!K:K, MATCH(CS24, ACC!I:I, 0)) = "", "-", INDEX(ACC!K:K, MATCH(CS24, ACC!I:I, 0))), "-" ) -> -
E27: 20 | H27: Inlet Pipe Size (A) | R27: Sch. No. | AX27: 65 | BA27: Enclosure | BQ27: =IF(CS17="", "-", CS17) -> - | CR27: ㄴ Supply Setting Pressure | CS27: =IFERROR( IF(INDEX(ACC!J:J, MATCH(CS24, ACC!I:I, 0)) = "", "-", INDEX(ACC!J:J, MATCH(CS24, ACC!I:I, 0))), "-" ) -> -
E28: 21 | H28: Outlet Pipe Size (A) | R28: Sch. No. | AX28: 66 | BA28: Model No. | BI28: MFG. | BQ28: =IF(CS14="", "-", CS14) -> - | CA28: =IF(CS13="", "-", CS13) -> - | CR28: Volume booster
A29: BODY & TRIM | E29: 22 | H29: Body Type | Y29: 2 | AT29: LIMIT SWITCH | AX29: 67 | BA29: Quantity | BQ29: =CS21 -> - | CR29: ㄴ MODEL | CS29: =IFERROR( IF(INDEX(ACC!AH:AH, MATCH(CS28, ACC!AG:AG, 0)) = "", "-", INDEX(ACC!AH:AH, MATCH(CS28, ACC!AG:AG, 0))), "-" ) -> -
E30: 23 | H30: Body Size | R30: Port Size | Y30: 5 | AJ30: 126 | AX30: 68 | BA30: Type | BQ30: =CS22 -> - | CR30: Air Operated Valve
E31: 24 | H31: Trim Design | Y31: 69 | AX31: 69 | BA31: Enclosure | BQ31: =CS23 -> - | CR31: ㄴ MODEL | CS31: =IFERROR( IF(INDEX(ACC!AE:AE, MATCH(CS30, ACC!AF:AF, 0)) = "", "-", INDEX(ACC!AE:AE, MATCH(CS30, ACC!AF:AF, 0))), "-" ) -> -
E32: 25 | H32: Trim Type | Y32: 125 | AX32: 70 | BA32: Model No. | BI32: MFG. | BQ32: =CS20 -> - | CA32: =CS19 -> - | CR32: Lockup valve
E33: 26 | H33: Trim Seal Ring | R33: Guide | AT33: LOCK-UP VALVE | AX33: 71 | BA33: Setting Pressure (bar G) | BQ33: =CS34 -> - | CR33: ㄴ MODEL | CS33: =IFERROR( IF(INDEX(ACC!AA:AA, MATCH(CS32, ACC!Y:Y, 0)) = "", "-", INDEX(ACC!AA:AA, MATCH(CS32, ACC!Y:Y, 0))), "-" ) -> -
E34: 27 | H34: Rating & End Connection | Y34: 157 | AX34: 72 | BA34: Model No. | BQ34: =CS33 -> - | CR34: ㄴ Setting Pressure | CS34: =IFERROR( IF(INDEX(ACC!Z:Z, MATCH(CS32, ACC!Y:Y, 0)) = "", "-", INDEX(ACC!Z:Z, MATCH(CS32, ACC!Y:Y, 0))), "-" ) -> -
E35: 28 | H35: Flange Facing | AT35: SNAP-ACTING RELAY | AX35: 73 | BA35: Setting Pressure (bar G) | BQ35: =CS37 -> - | CR35: Snap-acting relay
E36: 29 | H36: Material | R36: Body | Y36: 6 | AX36: 74 | BA36: Model No. | BQ36: =CS36 -> - | CR36: ㄴ MODEL | CS36: =IFERROR( IF(INDEX(ACC!AD:AD, MATCH(CS35, ACC!AB:AB, 0)) = "", "-", INDEX(ACC!AD:AD, MATCH(CS35, ACC!AB:AB, 0))), "-" ) -> -
E37: 30 | R37: Trim | Y37: 7 | AT37: ACCESSORY | AX37: 75 | BA37: Air-Operated Valve | BQ37: =CS31 -> - | CR37: ㄴ Setting Pressure | CS37: =IFERROR( IF(INDEX(ACC!AC:AC, MATCH(CS35, ACC!AB:AB, 0)) = "", "-", INDEX(ACC!AC:AC, MATCH(CS35, ACC!AB:AB, 0))), "-" ) -> -
E38: 31 | R38: Stem | AX38: 76 | BA38: Mechanical Valve
E39: 32 | R39: Packing | AX39: 77 | BA39: Check Valve
E40: 33 | AX40: 78 | BA40: Volume Booster | BQ40: =CS29 -> -
...

Sheet ACT
A1: ■ ACTUATOR (1/2) | G1: ■ ACTUATOR (2/2) | N1: ■ HANDLE
A2: 시리즈 | B2: 입력값 | C2: 출력값 | G2: 시리즈 | H2: 입력값 | J2: 출력값 | N2: 입력값 | O2: 출력값
B3: Act Size | C3: Model No. | D3: Painting Color | E3: Painting Type | F3: Actuator Type (2) | H3: Act Series | I3: Action Type | J3: Fail Position | K3: CLOSE AT | L3: OPEN AT | M3: Actuator Type (1) | N3: H.W | O3: Type / Location | P3: Painting Color (RAL No.) | Q3: Painting Type
A4: A 시리즈 [PROVAL] | B4: A-220M | C4: A-220M | F4: Diaphragm | G4: A 시리즈 [PROVAL] | H4: A시리즈 | I4: RA (Close) | J4: Close | K4: 1.4 | L4: 2.8 | M4: Single Acting | N4: - | O4: - | P4: - | Q4: -
B5: A-270M | C5: A-270M | D5: RAL 5019 | E5: Polyurethane | F5: Diaphragm | H5: A시리즈 | I5: DA (Open) | J5: Open | K5: 1.4 | L5: 0.7 | M5: Single Acting | N5: Screwed | O5: Screwed | P5: RAL 9011 | Q5: Polyurethane
B6: A-360M | C6: A-360M | D6: RAL 5019 | E6: Polyurethane | F6: Diaphragm | H6: A시리즈 | I6: Double | M6: Double Acting | N6: Screwed / Top | O6: Screwed / Top | P6: RAL 9011 | Q6: Polyurethane
B7: A-430M | C7: A-430M | D7: RAL 5019 | E7: Polyurethane | F7: Diaphragm | H7: A시리즈 | I7: SPECIAL | N7: Screwed / Side | O7: Screwed / Side | P7: RAL 9011 | Q7: Polyurethane
B8: A-520M | C8: A-520M | D8: RAL 5019 | E8: Polyurethane | F8: Diaphragm | G8: B시리즈 | H8: B시리즈 | I8: RA (Close) | J8: Close | K8: 2 | L8: 3.5 | M8: Single Acting | N8: Worm-Gear-Top | O8: Worm-Gear / Top | P8: RAL 9011 | Q8: Polyurethane
A9: B시리즈 | B9: B1 | C9: B1S | D9: RAL 9011 | E9: PX8576(S) -BLACK(AB-1) | F9: Cylinder | H9: B시리즈 | I9: DA (Open) | J9: Open | K9: 3.5 | L9: 2 | M9: Single Acting | N9: Worm-Gear-Side | O9: Worm-Gear / Side | P9: RAL 9011 | Q9: Polyurethane
B10: B2 | C10: B2S | D10: RAL 9011 | E10: Polyurethane | F10: Cylinder | H10: B시리즈 | I10: Double | J10: Last | K10: 4 | L10: 4 | M10: Double Acting | N10: Declutchable | O10: Declutchable | P10: RAL 9011 | Q10: Polyurethane
B11: B3 | C11: B3S | D11: RAL 5019 | E11: Polyurethane | F11: Cylinder | H11: B시리즈 | I11: SPECIAL | N11: SPECIAL
B12: B4 | C12: B4S | D12: RAL 5019 | E12: Polyurethane | F12: Cylinder | G12: C시리즈 | H12: C시리즈 | I12: RA (Close) | J12: Close | K12: 2.5 | L12: 3.5 | M12: Single Acting
B13: B5 | C13: B5S | D13: RAL 5019 | E13: Polyurethane | F13: Cylinder | H13: C시리즈 | I13: DA (Open) | J13: Open | K13: 3.5 | L13: 2.5 | M13: Single Acting
B14: B6 | C14: B6S | D14: RAL 5019 | E14: Polyurethane | F14: Cylinder | H14: C시리즈 | I14: Double | J14: Last | K14: 4 | L14: 4 | M14: Double Acting
A15: C시리즈 | B15: C-160 | C15: C-160 | D15: RAL 5019 | E15: Polyurethane | F15: Cylinder | H15: C시리즈 | I15: SPECIAL
B16: C-200 | C16: C-200 | D16: RAL 5019 | E16: Polyurethane | F16: Cylinder | G16: DB시리즈 | H16: DB시리즈 | I16: RA (Close) | J16: Close | K16: 1.2 | L16: 2.4 | M16: Single Acting
B17: C-250 | C17: C-250 | D17: RAL 5019 | E17: Polyurethane | F17: Cylinder | H17: DB시리즈 | I17: DA (Open) | J17: Open | K17: 2 | L17: 1.2 | M17: Single Acting
B18: C-300 | C18: C-300S | D18: RAL 5019 | E18: Polyurethane | F18: Cylinder | H18: DB시리즈 | I18: Double | M18: Double Acting
B19: C-350 | C19: C-350S | D19: RAL 5019 | E19: Polyurethane | F19: Cylinder | H19: DB시리즈 | I19: SPECIAL
B20: C-400 | C20: C-400S | F20: Cylinder | G20: CB시리즈 | H20: CB시리즈 | I20: RA (Close) | J20: Close | M20: Single Acting
B21: C-450 | C21: C-450S | F21: Cylinder | H21: CB시리즈 | I21: DA (Open) | J21: Open | K21: 3.5 | L21: 2 | M21: Single Acting
B22: C-500 | C22: C-500S | F22: Cylinder | H22: CB시리즈 | I22: Double | M22: Double Acting
A23: DB시리즈 | B23: DB-270 | C23: DB-270 | D23: RAL 5019 | E23: Polyurethane | F23: Diaphragm | H23: CB시리즈 | I23: SPECIAL
B24: DB-360 | C24: DB-360 | D24: RAL 5019 | E24: Polyurethane | F24: Diaphragm | G24: Float | H24: Float | I24: RA (Close) | J24: Close | K24: Low Level | L24: High Level | M24: Levered
B25: DB-430 | C25: DB-430 | D25: RAL 5019 | E25: Polyurethane | F25: Diaphragm | H25: Float | I25: DA (Open) | J25: Open | K25: High Level | L25: Low Level | M25: Levered
B26: DB-520 | C26: DB-520 | F26: Diaphragm | H26: Float | I26: Double | M26: Levered
A27: CB시리즈 | B27: CB-270 | C27: CB-270 | F27: Cylinder | H27: Float | I27: SPECIAL
B28: CB-360 | C28: CB-360 | D28: RAL 5019 | E28: Polyurethane | F28: Cylinder | G28: (HKC)HP시리즈 | H28: (HKC)HP시리즈 | I28: RA (Close) | J28: Close | K28: 2.5 | L28: 3.5 | M28: Single Acting
B29: CB-430 | C29: CB-430 | F29: Cylinder | H29: (HKC)HP시리즈 | I29: DA (Open) | J29: Open | K29: 3.5 | L29: 2 | M29: Single Acting
B30: CB-520 | C30: CB-520 | F30: Cylinder | H30: (HKC)HP시리즈 | I30: Double | J30: Close / Last | M30: Double Acting
A31: Float | B31: 25A용 | C31: YAF | D31: - | E31: - | F31: Float | H31: (HKC)HP시리즈 | I31: SPECIAL
B32: 40-50A용 | C32: YAF | D32: - | E32: - | F32: Float | G32: (성원)PM시리즈 | H32: (성원)PM시리즈 | I32: RA (Close) | J32: Close | K32: 2 | L32: 3.5 | M32: Single Acting
A33: (HKC)HP시리즈 | B33: HP-88 (B1) | C33: B1S | D33: RAL 9011 | E33: PX8576(S) -BLACK(AB-1) | F33: Cylinder | H33: (성원)PM시리즈 | I33: DA (Open) | J33: Open | K33: 3.5 | L33: 2 | M33: Single Acting
B34: HP-100 (B2) | C34: B2SR | D34: RAL 9011 | E34: PX8576(S) -BLACK(AB-1) | F34: Cylinder | H34: (성원)PM시리즈 | I34: Double | M34: Double Acting
B35: HP-125 (B4) | C35: B4SR | D35: RAL 9011 | E35: PX8576(S) -BLACK(AB-1) | F35: Cylinder | H35: (성원)PM시리즈 | I35: SPECIAL
B36: HP-66 (B0) | C36: B0SR | F36: Cylinder | G36: R시리즈 | H36: R시리즈 | I36: RA (Close) | J36: Close | K36: 2 | L36: 3.5 | M36: Single Acting
B37: HP-115(B3) | C37: B3SR | F37: Cylinder | H37: R시리즈 | I37: DA (Open) | J37: Open | K37: 3.5 | L37: 2 | M37: Single Acting
B38: HP-145 (B6) | C38: B6SR | D38: RAL 9011 | E38: PX8576(S) -BLACK(AB-1) | F38: Cylinder | H38: R시리즈 | I38: Double | J38: Last | K38: 4 | L38: 4 | M38: Double Acting
B39: HP-160 | C39: HP-160 | F39: Cylinder | H39: R시리즈 | I39: SPECIAL
B40: HP-200 | C40: HP-200 | F40: Cylinder | G40: C V/T시리즈 | H40: C V/T시리즈 | I40: RA (Close) | J40: Close | M40: Single Acting
...

Sheet ACC
A1: ■ POSITIONER | I1: ■ AIR-SET | M1: ■ SOLENOID VALVE | S1: ■ LIMIT SWITCH | Y1: ■ LOCKUP VALVE | AB1: ■ SNAP-ACTING RELAY | AE1: ■ AIR OPERATED VALVE | AG1: ■ VOLUME BOOSTER
A2: 입력값 | B2: 출력값 (POSITIONER) | G2: 출력값 (TRANSMITTER) | I2: 입력값 | J2: 출력값 | M2: 입력값 | N2: 출력값 | S2: 입력값 | T2: 출력값 | Y2: 입력값 | Z2: 출력값 | AB2: 입력값 | AC2: 출력값 | AE2: 입력값 | AF2: 출력값 | AG2: 입력값 | AH2: 출력값
A3: Positioner | B3: Input Signal (mA DC) | C3: Type | D3: Enclosure | E3: Model No. | F3: MFG. | G3: Output (mA DC) | H3: Type | I3: Air-set | J3: Supply Setting Pressure (bar G) | K3: Model No. | L3: MFG. | M3: Solenoid Valve | N3: Power | O3: Type | P3: Enclosure | Q3: Model No. | R3: MFG. | S3: Limit Switch | T3: Quantity | U3: Type | V3: Enclosure | W3: Model No. | X3: MFG. | Y3: Lockup valve | Z3: Setting Pressure (bar G) | AA3: Model No. | AB3: SNAP-ACTING RELAY | AC3: Setting Pressure (bar G) | AD3: Model No. | AE3: Air Operated Valve | AF3: Model No. | AG3: Volume booster | AH3: Model No.
A4: AVP300-HSD3D-XXXX-X | B4: 4 ~ 20 | C4: Smart | D4: ExdIICT6 | E4: AVP-300 | F4: Azbil | G4: - | H4: - | I4: AR-1501NS0(TS300) | J4: 4 | K4: AR-1501 | L4: Proval | M4: 4F310-08-TP-X-DC24V | N4: DC24V | O4: 5-Way | P4: IP-66 | Q4: 4F310E-08 | R4: CKD | S4: APL-210N | T4: Close/Open | U4: SPDT | V4: IP-66 | W4: APL-210N | X4: HKC | Y4: LV-2000DNS(TS200) | Z4: - | AA4: LV-2000D | AB4: SAR25D(TS250) | AC4: 1.4 | AD4: SAR25D | AE4: SFP4313 | AF4: SFP4313 | AG4: VB-1000NS(TS100) | AH4: VB-1000
A5: AVP302-HSD3D-XXXX-X | B5: 4 ~ 20 | C5: Smart-Hart | D5: ExdIICT6 | E5: AVP-302 | F5: Azbil | G5: - | H5: - | I5: AR-1501PS0(TS300) | J5: 3.6 | K5: AR-1501 | L5: Proval | M5: 4F310-10-B-DC24V | N5: DC24V | O5: 3-Way | P5: IP-66 | Q5: 4F310-10-B | R5: CKD | S5: APL-312N | T5: Close/Open | U5: 4SPDT | V5: IP-66 | W5: APL-312N | X5: HKC | Y5: LV-2000SNS(TS200) | AA5: LV-2000S | AE5: SFP6313 | AF5: SFP6313 | AG5: VB-1000PS(TS100) | AH5: VB-1000
A6: EP-6000LN12S0(TS600) | B6: 4 ~ 20 | C6: Conventional | D6: IP-66 | E6: EP-6000 | F6: Proval | G6: - | H6: - | I6: AR-2501NS0(TS310) | K6: AR-2501 | L6: Proval | M6: 4F310E-08-TP-X-AC110V | N6: AC110V | O6: 5-Way | P6: ExdIIBT4 | Q6: 4F310E-08 | R6: CKD | S6: APL-314N | T6: Close/Open | U6: DPDT | V6: IP-66 | W6: APL-314N | X6: HKC | Y6: LV-2000SPS(TS200) | Z6: 2 | AA6: LV-2000S | AE6: SV-210M | AF6: SV-210M | AG6: YT-320P-1 | AH6: YT-320P-1
A7: EP-6100RN11S0 | C7: Conventional | D7: NEMA 4 | E7: EP-6100 | F7: Proval | I7: AW30-03-A | K7: AW30-03-A | M7: 4F310E-08-TP-X-DC24V | N7: DC24V | O7: 4-Way | P7: IP-66 | Q7: 4F310-08 | R7: CKD | S7: APL-510N | W7: APL-510N | X7: HKC | AE7: SV-310M | AF7: 3-Way
A8: IP8100-031-CH-X114 | B8: 4 ~ 20 | C8: Conventional | D8: ExdIIBT5 | E8: IP-8100 | F8: SM | G8: - | H8: - | I8: B7019-2C-M | K8: B7019-2C-M | M8: ESV-S-A110P-F | N8: AC110V | O8: 5/2-Way | P8: EXdIICT6 | Q8: ESV-S | R8: PG | S8: APL-512N | T8: Close/Open | U8: 4SPDT | V8: ExdIICT6 | W8: APL-512N | X8: HKC | AE8: SV-410M | AF8: SV-410M
A9: SP-8000N11S10(TS800) | B9: 4 ~ 20 | C9: Smart | D9: IP-66 | E9: SP-8000 | F9: Proval | G9: 4 ~ 20 | H9: 2-Wire | I9: TS300PS0 | J9: 5 | K9: TS300 | L9: TSC | M9: ESV-S-A220P-F | N9: AC220V | O9: 5/2-Way | P9: EXdIICT6 | Q9: ESV-S | R9: PG | S9: GLAA20A2A | T9: Close/Open | U9: DPDT | V9: IP-66 | W9: GLAA20A2A | X9: Honeywell
A10: SP-8000N11S30(TS800) | B10: 4 ~ 20 | C10: Smart-Hart | D10: IP-66 | E10: SP-8000 | F10: Proval | G10: 4 ~ 20 | H10: 2-Wire | I10: YT-200BN020 | J10: 3.6 | K10: YT-200-2 (고온용) | L10: Rotork | M10: ESV-S-D24P-F | N10: DC24V | O10: 5/2-Way | P10: ExdIICT6 | Q10: ESV-S | R10: PG | S10: SLP5130-AL | T10: Close/Open | U10: SPDT | V10: ExdIICT6 | W10: SLP5130-AL | X10: Qlight
A11: SP-8100N11S30(TS800) | B11: 4 ~ 20 | C11: Smart-Hart | D11: IP-66 | E11: SP-8100 | F11: Proval | G11: 4 ~ 20 | H11: 2-Wire | I11: YT-200BP010 | J11: 3.6 | K11: YT-200 | L11: Rotork | M11: HKW5020B | S11: SZL-WLC-B | T11: 1*Close | U11: SPDT | V11: IP-66 | W11: SZL-WLC-B | X11: Honeywell
A12: TS600LB12S0 | B12: 4 ~ 20 | C12: Conventional | D12: ExdIIBT5 | E12: TS600L | F12: TSC | G12: - | H12: - | I12: YT-200BP020 | K12: YT-200-H | M12: HKW5020S | S12: TS400M1S1 | T12: Close/Open | U12: SPDT | V12: IP-66 | W12: TS-400 | X12: TSC
A13: TS600LC12S0 | B13: 4 ~ 20 | C13: Conventional | D13: ExdIICT5 | E13: TS600LC | F13: TSC | G13: - | H13: - | I13: YT-220BN010 | K13: YT-220 | M13: HPW2510B | S13: TS410MK1S1 | T13: Close/Open | U13: SPDT | V13: ExdIICT5/T6 | W13: TS-410 | X13: TSC
A14: TS600LN12S1 | C14: Conventional | D14: IP-66 | E14: TS600L | F14: TSC | M14: HPW2510SB
A15: TS600RB11S0 | B15: 4 ~ 20 | C15: Conventional | D15: ExdIIBT5 | E15: TS600R | F15: TSC | G15: - | H15: - | M15: HPW3212B
A16: TS600RN11S1 | B16: 4 ~ 20 | C16: Conventional | D16: IP-66 | E16: TS600RN | F16: TSC | G16: 4 ~ 20 | H16: 2-Wire | M16: JKB8320G174MO | N16: AC220V | O16: 3-Way, H-Class, Junction Box, Manual Operator | P16: IP-66 | Q16: JKB8320G174MO | R16: ASCO
A17: TS600RC11S0 | E17: TS600R-C | F17: TSC | M17: JKH8320G174M0 | N17: DC24V / 2Set | O17: 3-Way, H-Class | P17: IP-66 | Q17: JKH8320G174MO | R17: ASCO
A18: TS700LSN11S10 | C18: Smart, Fail Freeze | D18: IP-66 | E18: TS700L | F18: TSC | M18: MOOU-8AE-12PU-AC110V | N18: AC110V | O18: 3-Way | P18: ExdIIBT4 | Q18: MOOU-8AE-12PU | R18: KANEKO
A19: TS800RA11S10 | B19: 4 ~ 20 | C19: Smart | D19: Exia II CT6 | E19: TS800RA | F19: TSC | G19: 4 ~ 20 | H19: 15~30V DC / 2-Wire | M19: MOOU-8AE-12PU-AC220V | Q19: MOOU-8AE-12PU | R19: KANEKO
A20: TS820RA11S01 | C20: Smart, Remote, 5m | D20: ExiaIICT5/T6 | E20: TS820R | F20: TSC | M20: MOOU-8DE-12PU-DC24V | N20: DC24V | O20: 3-Way | P20: ExdIIBT4 | Q20: MOOU-8DE-12PU | R20: KANEKO
A21: TS900LC31S10 | B21: 4 ~ 20 | C21: Smart | D21: ExdIICT6 | E21: TS900L | F21: TSC | G21: - | H21: - | M21: RDS5120-1DZ-03 | N21: AC110V | O21: 5-Way | P21: IP-66 | Q21: RDS5120-03 | R21: TPC
A22: TS900LC31S20 | E22: TS900L | F22: TSC | M22: SV-210-1D | N22: AC110V | O22: 3-Way, 램프형 | P22: IP-66 | Q22: SV-210D | R22: SYC
A23: TS900LC31S30 | E23: TS900L | F23: TSC | M23: SV-210-1D-LAMP | Q23: SV-210D | R23: SYC
A24: TS900RC31S10 | B24: 4 ~ 20 | C24: Smart | D24: ExdIICT6 | E24: TS900R | F24: TSC | G24: 4 ~ 20 | H24: 2-Wire | M24: SV-210-1D-LOCK LEVER | N24: AC110V | O24: 3-Way, Lock Lever Type, 램프형 | P24: IP-66 | Q24: SV-210D | R24: SYC
A25: YT-1000LSC231S0 | B25: 4 ~ 20 | C25: Conventional | D25: ExdIICT5 | E25: YT-1000L-C | F25: Rotork | G25: - | H25: - | M25: SV-210-1D-LOCK LEVER+LAMP | Q25: SV-210D | R25: SYC
A26: YT-1000LSM231S0 | B26: 4 ~ 20 | C26: Conventional | D26: ExdIIBT5 | E26: YT-1000L | F26: Rotork | G26: - | H26: - | M26: SV-210-2D | N26: AC220V | O26: 3-Way | P26: IP-66 | Q26: SV-210D | R26: SYC
A27: YT-1000RSM231S0 | C27: Conventional | D27: ExdIIBT5 | E27: YT-1000R | F27: Rotork | M27: SV-210-2D-LAMP | Q27: SV-210D | R27: SYC
A28: YT-1200LS231S0 | E28: YT-1200L | F28: Rotork | M28: SV-210-2D-LOCK LEVER | Q28: SV-210D | R28: SYC
A29: YT-3300LSN1101S | E29: YT-3300L | F29: Rotork | M29: SV-210-2D-LOCK LEVER+LAMP | Q29: SV-210D | R29: SYC
A30: YT-3300LSN1120S | E30: YT-3300L | F30: Rotork | M30: SV-210-4D-LAMP | Q30: SV-210D | R30: SYC
A31: YT-3300LSN1121S | E31: YT-3300L | F31: Rotork | M31: SV-210-4D-LOCK LEVER | N31: DC24V | O31: 5-Way, Lock Type | P31: IP-66 | Q31: SV-210D | R31: SYC
A32: YT-3300RSN2120S | C32: Smart-Hart | D32: IP-66 | E32: YT-3300R | F32: Rotork | M32: SV-210-4D-LOCK LEVER+LAMP | Q32: SV-210D | R32: SYC
A33: YT-3303LDN2121S | B33: 4 ~ 20 | C33: Smart-Hart | D33: IP-66 | E33: YT-3303LD | F33: Rotork | G33: 4 ~ 20 | H33: 2-Wire | M33: SV-410-1D-LOCK LEVER | Q33: SV-410D | R33: SYC
A34: YT-3303LSN2100S | B34: 4 ~ 20 | C34: Smart | D34: IP-66 | E34: YT-3303L | F34: Rotork | G34: 4 ~ 20 | H34: 2-Wire | M34: VCEFCMHBX8320G174MO-AC110V | N34: AC110V | O34: 3-Way, Manual Operator | P34: ExdIICT6 | Q34: VCEFCMHBX8320G174MO | R34: ASCO
A35: YT-3303LSN2101S | B35: 4 ~ 20 | C35: Smart | D35: IP-66 | E35: YT-3303L | F35: Rotork | G35: - | H35: - | M35: VCEFCMHBX8320G174MO-AC220V | N35: AC220V | O35: 3-Way, H-Class, Junction Box, Manual Operator | P35: ExdIICT3 | Q35: VCEFCMHBX8320G174MO | R35: ASCO
A36: YT-3303LSN2120S | C36: Smart-Hart | D36: IP-66 | E36: YT-3303L | F36: Rotork
A37: YT-3303LSN2121S | B37: 4 ~ 20 | C37: Smart-Hart | D37: IP-66 | E37: YT-3303L | F37: Rotork | G37: 4 ~ 20 | H37: 2-Wire
A38: YT-3400LDC2121S | C38: Smart-Hart | D38: ExdIICT6 | E38: YT-3400LD | F38: Rotork
A39: YT-3400LSC2100S | C39: Smart | D39: ExdIICT6 | E39: YT-3400L | F39: Rotork
A40: YT-3400LSC2101S | B40: 4 ~ 20 | C40: Smart | D40: ExdIICT6 | E40: YT-3400L | F40: Rotork | G40: 4 ~ 20 | H40: 2-Wire
...
